<?xml version="1.0" encoding="utf-8"?>
<!-- =================================================================================== -->
<!-- |    This document was autogenerated by xacro from fake_car.urdf.xacro            | -->
<!-- |    EDITING THIS FILE BY HAND IS NOT RECOMMENDED                                 | -->
<!-- =================================================================================== -->
<robot name="fake_car" xmlns:xacro="http://ros.org/wiki/xacro">
  <link name="base_link">
    <visual>
      <origin rpy="0 0 0" xyz="0 0 0.1"/>
      <geometry>
        <cylinder length="0.2" radius="0.01"/>
      </geometry>
      <material name="silver">
        <color rgba="0.75 0.75 0.75 1"/>
      </material>
    </visual>
    <collision>
      <origin rpy="0 0 0" xyz="0 0 0.1"/>
      <geometry>
        <cylinder length="0.2" radius="0.01"/>
      </geometry>
    </collision>
    <inertial>
      <mass value="0.01"/>
      <inertia ixx="0.015" ixy="0" ixz="0" iyy="0.0375" iyz="0" izz="0.0375"/>
    </inertial>
  </link>
  <link name="chassis_link">
    <visual>
      <geometry>
        <box size="0.3429 0.25 0.06"/>
      </geometry>
    </visual>
    <collision>
      <geometry>
        <box size="0.3429 0.25 0.06"/>
      </geometry>
    </collision>
    <inertial>
      <mass value="2.6"/>
      <inertia ixx="0.0143216666667" ixy="0" ixz="0" iyy="0.0262557555" iyz="0" izz="0.0262557555"/>
    </inertial>
  </link>
  <link name="back_left_wheel">
    <visual>
      <geometry>
        <cylinder length="0.047" radius="0.056"/>
      </geometry>
      <material name="black">
        <color rgba="0 0 0 1"/>
      </material>
    </visual>
    <collision>
      <geometry>
        <cylinder length="0.047" radius="0.056"/>
      </geometry>
    </collision>
    <inertial>
      <mass value="0.1"/>
      <inertia ixx="9.68083333333e-05" ixy="0" ixz="0" iyy="9.68083333333e-05" iyz="0" izz="0.0001568"/>
    </inertial>
  </link>
  <link name="laser_scanner_link">
    <collision>
      <origin rpy="0 0 0" xyz="0 0 0"/>
      <geometry>
        <box size=".127 0.1016 0.0508"/>
      </geometry>
    </collision>
    <visual>
      <origin rpy="0 0 0" xyz="0 0 0"/>
      <geometry>
        <box size=".127 0.1016 0.0508"/>
      </geometry>
    </visual>
    <inertial>
      <mass value="1e-5"/>
      <origin rpy="0 0 0" xyz="0 0 0"/>
      <inertia ixx="1e-6" ixy="0" ixz="0" iyy="1e-6" iyz="0" izz="1e-6"/>
    </inertial>
  </link>
  <joint name="laser_scanner_joint" type="fixed">
    <origin rpy="0 0 0" xyz="0.1397 0 0.2159"/>
    <parent link="base_link"/>
    <child link="laser_scanner_link"/>
  </joint>
  <gazebo reference="laser_scanner_link">
    <sensor name="laser_scanner" type="gpu_ray">
      <pose>0 0 0 0 0 0</pose>
      <visualize>true</visualize>
      <update_rate>20</update_rate>
      <ray>
        <scan>
          <horizontal>
            <samples>360</samples>
            <resolution>1</resolution>
            <min_angle>-3.14159265359</min_angle>
            <max_angle>3.14159265359</max_angle>
          </horizontal>
        </scan>
        <range>
          <min>0.10</min>
          <max>15.0</max>
          <resolution>0.1</resolution>
        </range>
      </ray>
      <plugin filename="libgazebo_ros_gpu_laser.so" name="gpu_laser">
        <topicName>/scan</topicName>
        <frameName>laser_scanner_link</frameName>
      </plugin>
    </sensor>
  </gazebo>
  <link name="back_right_wheel">
    <visual>
      <geometry>
        <cylinder length="0.047" radius="0.056"/>
      </geometry>
      <material name="black">
        <color rgba="0 0 0 1"/>
      </material>
    </visual>
    <collision>
      <geometry>
        <cylinder length="0.047" radius="0.056"/>
      </geometry>
    </collision>
    <inertial>
      <mass value="0.1"/>
      <inertia ixx="9.68083333333e-05" ixy="0" ixz="0" iyy="9.68083333333e-05" iyz="0" izz="0.0001568"/>
    </inertial>
  </link>
  <link name="front_left_wheel_steer">
    <visual>
      <geometry>
        <cylinder length="0.01" radius="0.01"/>
      </geometry>
      <material name="black">
        <color rgba="0 0 0 1"/>
      </material>
    </visual>
    <collision>
      <geometry>
        <cylinder length="0.01" radius="0.01"/>
      </geometry>
    </collision>
    <inertial>
      <mass value="0.1"/>
      <inertia ixx="5.1458e-5" ixy="0" ixz="0" iyy="5.1458e-5" iyz="0" izz="6.125e-5"/>
    </inertial>
  </link>
  <link name="front_left_wheel">
    <visual>
      <geometry>
        <cylinder length="0.047" radius="0.056"/>
      </geometry>
      <material name="black">
        <color rgba="0 0 0 1"/>
      </material>
    </visual>
    <collision>
      <geometry>
        <cylinder length="0.047" radius="0.056"/>
      </geometry>
    </collision>
    <inertial>
      <mass value="0.1"/>
      <inertia ixx="9.68083333333e-05" ixy="0" ixz="0" iyy="9.68083333333e-05" iyz="0" izz="0.0001568"/>
    </inertial>
  </link>
  <link name="front_right_wheel_steer">
    <visual>
      <geometry>
        <cylinder length="0.01" radius="0.01"/>
      </geometry>
      <material name="black">
        <color rgba="0 0 0 1"/>
      </material>
    </visual>
    <collision>
      <geometry>
        <cylinder length="0.01" radius="0.01"/>
      </geometry>
    </collision>
    <inertial>
      <mass value="0.1"/>
      <inertia ixx="5.1458e-5" ixy="0" ixz="0" iyy="5.1458e-5" iyz="0" izz="6.125e-5"/>
    </inertial>
  </link>
  <link name="front_right_wheel">
    <visual>
      <geometry>
        <cylinder length="0.047" radius="0.056"/>
      </geometry>
      <material name="black">
        <color rgba="0 0 0 1"/>
      </material>
    </visual>
    <collision>
      <geometry>
        <cylinder length="0.047" radius="0.056"/>
      </geometry>
    </collision>
    <inertial>
      <mass value="0.1"/>
      <inertia ixx="9.68083333333e-05" ixy="0" ixz="0" iyy="9.68083333333e-05" iyz="0" izz="0.0001568"/>
    </inertial>
  </link>
  <link name="back_left_wheel_shock">
    <visual>
      <origin rpy="0 0 0" xyz="0 0 0.1"/>
      <geometry>
        <cylinder length="0.2" radius="0.01"/>
      </geometry>
      <material name="silver">
        <color rgba="0.75 0.75 0.75 1"/>
      </material>
    </visual>
    <collision>
      <origin rpy="0 0 0" xyz="0 0 0.1"/>
      <geometry>
        <cylinder length="0.2" radius="0.01"/>
      </geometry>
    </collision>
    <inertial>
      <mass value="0.01"/>
      <inertia ixx="0.015" ixy="0" ixz="0" iyy="0.0375" iyz="0" izz="0.0375"/>
    </inertial>
  </link>
  <joint name="back_left_shock_joint" type="prismatic">
    <limit effort="100" lower="0" upper="0.09" velocity="100"/>
    <axis xyz="0 0 1"/>
    <parent link="base_link"/>
    <child link="back_left_wheel_shock"/>
    <origin rpy="0 0 0" xyz="0 0.125  -0.045"/>
  </joint>
  <joint name="back_left_wheel_joint" type="continuous">
    <axis xyz="0 0 1"/>
    <parent link="back_left_wheel_shock"/>
    <child link="back_left_wheel"/>
    <origin rpy="-1.57079632679 0 0" xyz="0 0 0"/>
    <limit effort="10000" velocity="500"/>
  </joint>
  <link name="back_right_wheel_shock">
    <visual>
      <origin rpy="0 0 0" xyz="0 0 0.1"/>
      <geometry>
        <cylinder length="0.2" radius="0.01"/>
      </geometry>
      <material name="silver">
        <color rgba="0.75 0.75 0.75 1"/>
      </material>
    </visual>
    <collision>
      <origin rpy="0 0 0" xyz="0 0 0.1"/>
      <geometry>
        <cylinder length="0.2" radius="0.01"/>
      </geometry>
    </collision>
    <inertial>
      <mass value="0.01"/>
      <inertia ixx="0.015" ixy="0" ixz="0" iyy="0.0375" iyz="0" izz="0.0375"/>
    </inertial>
  </link>
  <joint name="back_right_shock_joint" type="prismatic">
    <limit effort="100" lower="0" upper="0.09" velocity="100"/>
    <axis xyz="0 0 1"/>
    <parent link="base_link"/>
    <child link="back_right_wheel_shock"/>
    <origin rpy="0 0 0" xyz="0 -0.125 -0.045"/>
  </joint>
  <joint name="back_right_wheel_joint" type="continuous">
    <axis xyz="0 0 1"/>
    <parent link="back_right_wheel_shock"/>
    <child link="back_right_wheel"/>
    <origin rpy="-1.57079632679 0 0" xyz="0 0 0"/>
    <limit effort="10000" velocity="500"/>
  </joint>
  <link name="front_left_wheel_shock">
    <visual>
      <origin rpy="0 0 0" xyz="0 0 0.1"/>
      <geometry>
        <cylinder length="0.2" radius="0.01"/>
      </geometry>
      <material name="silver">
        <color rgba="0.75 0.75 0.75 1"/>
      </material>
    </visual>
    <collision>
      <origin rpy="0 0 0" xyz="0 0 0.1"/>
      <geometry>
        <cylinder length="0.2" radius="0.01"/>
      </geometry>
    </collision>
    <inertial>
      <mass value="0.01"/>
      <inertia ixx="0.015" ixy="0" ixz="0" iyy="0.0375" iyz="0" izz="0.0375"/>
    </inertial>
  </link>
  <link name="front_right_wheel_shock">
    <visual>
      <origin rpy="0 0 0" xyz="0 0 0.1"/>
      <geometry>
        <cylinder length="0.2" radius="0.01"/>
      </geometry>
      <material name="silver">
        <color rgba="0.75 0.75 0.75 1"/>
      </material>
    </visual>
    <collision>
      <origin rpy="0 0 0" xyz="0 0 0.1"/>
      <geometry>
        <cylinder length="0.2" radius="0.01"/>
      </geometry>
    </collision>
    <inertial>
      <mass value="0.01"/>
      <inertia ixx="0.015" ixy="0" ixz="0" iyy="0.0375" iyz="0" izz="0.0375"/>
    </inertial>
  </link>
  <joint name="front_right_shock_joint" type="prismatic">
    <limit effort="100" lower="0" upper="0.09" velocity="100"/>
    <axis xyz="0 0 1"/>
    <parent link="base_link"/>
    <child link="front_right_wheel_shock"/>
    <origin rpy="0 0 0" xyz="0.3429 -0.125 -0.045"/>
  </joint>
  <joint name="front_left_shock_joint" type="prismatic">
    <limit effort="100" lower="0" upper="0.09" velocity="100"/>
    <axis xyz="0 0 1"/>
    <parent link="base_link"/>
    <child link="front_left_wheel_shock"/>
    <origin rpy="0 0 0" xyz="0.3429 0.125  -0.045"/>
  </joint>
  <joint name="front_left_wheel_steer_joint" type="revolute">
    <limit effort="1" lower="-1" upper="1" velocity="5"/>
    <axis xyz="0 0 1"/>
    <parent link="front_left_wheel_shock"/>
    <child link="front_left_wheel_steer"/>
    <origin rpy="0 0 0" xyz="0 0 0"/>
  </joint>
  <joint name="front_left_wheel_joint" type="continuous">
    <axis xyz="0 0 1"/>
    <parent link="front_left_wheel_steer"/>
    <child link="front_left_wheel"/>
    <origin rpy="-1.57079632679 0 0" xyz="0 0 0"/>
  </joint>
  <joint name="front_right_wheel_steer_joint" type="revolute">
    <limit effort="1" lower="-1" upper="1" velocity="5"/>
    <axis xyz="0 0 1"/>
    <parent link="front_right_wheel_shock"/>
    <child link="front_right_wheel_steer"/>
    <origin rpy="0 0 0" xyz="0 0 0"/>
  </joint>
  <joint name="front_right_wheel_joint" type="continuous">
    <axis xyz="0 0 1"/>
    <parent link="front_right_wheel_steer"/>
    <child link="front_right_wheel"/>
    <origin rpy="-1.57079632679 0 0" xyz="0 0 0"/>
  </joint>
  <joint name="chassis_joint" type="fixed">
    <parent link="base_link"/>
    <child link="chassis_link"/>
    <origin rpy="0 0 0" xyz="0.17145 0 0.02"/>
  </joint>
  <gazebo reference="front_left_wheel">
    <mu1>0.8</mu1>
    <material>Gazebo/DarkGrey</material>
  </gazebo>
  <gazebo reference="front_right_wheel">
    <mu1>0.8</mu1>
    <material>Gazebo/DarkGrey</material>
  </gazebo>
  <gazebo reference="back_left_wheel">
    <mu1>0.8</mu1>
    <material>Gazebo/DarkGrey</material>
  </gazebo>
  <gazebo reference="back_right_wheel">
    <mu1>0.8</mu1>
    <material>Gazebo/DarkGrey</material>
  </gazebo>
  <gazebo reference="base_link">
    <dampingFactor>0.00007</dampingFactor>
  </gazebo>
  <gazebo>
    <plugin filename="libfake_car_plugin.so" name="fake_car_plugin">
    </plugin>
  </gazebo>
</robot>

